<?xml version="1.0" encoding="UTF-8"?>
<testng-results skipped="0" failed="2" total="3" passed="1">
  <reporter-output>
  </reporter-output>
  <suite name="Default suite" duration-ms="125" started-at="2020-06-06T10:48:11Z" finished-at="2020-06-06T10:48:11Z">
    <groups>
    </groups>
    <test name="Default test" duration-ms="125" started-at="2020-06-06T10:48:11Z" finished-at="2020-06-06T10:48:11Z">
      <class name="MyTest.SoftAssertConcepts">
        <test-method status="PASS" signature="tearDown()[pri:0, instance:MyTest.SoftAssertConcepts@d70c109]" name="tearDown" duration-ms="27" started-at="2020-06-06T16:18:11Z" finished-at="2020-06-06T16:18:11Z">
          <reporter-output>
          </reporter-output>
        </test-method> <!-- tearDown -->
        <test-method status="FAIL" signature="test1()[pri:0, instance:MyTest.SoftAssertConcepts@d70c109]" name="test1" duration-ms="22" started-at="2020-06-06T16:18:11Z" finished-at="2020-06-06T16:18:11Z">
          <exception class="java.lang.AssertionError">
            <message>
              <![CDATA[The following asserts failed:
Home Page title is missing expected [true] but found [false], Not able to create a Deal expected [true] but found [false], Not able to create a Contacts expected [true] but found [false]]]>
            </message>
            <full-stacktrace>
              <![CDATA[java.lang.AssertionError: The following asserts failed:
Home Page title is missing expected [true] but found [false], Not able to create a Deal expected [true] but found [false], Not able to create a Contacts expected [true] but found [false]
	at org.testng.asserts.SoftAssert.assertAll(SoftAssert.java:38)
	at MyTest.SoftAssertConcepts.test1(SoftAssertConcepts.java:34)
	at sun.reflect.NativeMethodAccessorImpl.invoke0(Native Method)
	at sun.reflect.NativeMethodAccessorImpl.invoke(Unknown Source)
	at sun.reflect.DelegatingMethodAccessorImpl.invoke(Unknown Source)
	at java.lang.reflect.Method.invoke(Unknown Source)
	at org.testng.internal.MethodInvocationHelper.invokeMethod(MethodInvocationHelper.java:85)
	at org.testng.internal.Invoker.invokeMethod(Invoker.java:663)
	at org.testng.internal.Invoker.invokeTestMethod(Invoker.java:849)
	at org.testng.internal.Invoker.invokeTestMethods(Invoker.java:1157)
	at org.testng.internal.TestMethodWorker.invokeTestMethods(TestMethodWorker.java:124)
	at org.testng.internal.TestMethodWorker.run(TestMethodWorker.java:108)
	at org.testng.TestRunner.privateRun(TestRunner.java:771)
	at org.testng.TestRunner.run(TestRunner.java:621)
	at org.testng.SuiteRunner.runTest(SuiteRunner.java:357)
	at org.testng.SuiteRunner.runSequentially(SuiteRunner.java:352)
	at org.testng.SuiteRunner.privateRun(SuiteRunner.java:310)
	at org.testng.SuiteRunner.run(SuiteRunner.java:259)
	at org.testng.SuiteRunnerWorker.runSuite(SuiteRunnerWorker.java:52)
	at org.testng.SuiteRunnerWorker.run(SuiteRunnerWorker.java:86)
	at org.testng.TestNG.runSuitesSequentially(TestNG.java:1200)
	at org.testng.TestNG.runSuitesLocally(TestNG.java:1125)
	at org.testng.TestNG.run(TestNG.java:1033)
	at org.testng.remote.RemoteTestNG.run(RemoteTestNG.java:111)
	at org.testng.remote.RemoteTestNG.initAndRun(RemoteTestNG.java:204)
	at org.testng.remote.RemoteTestNG.main(RemoteTestNG.java:175)
]]>
            </full-stacktrace>
          </exception> <!-- java.lang.AssertionError -->
          <reporter-output>
          </reporter-output>
        </test-method> <!-- test1 -->
        <test-method status="FAIL" signature="test2()[pri:0, instance:MyTest.SoftAssertConcepts@d70c109]" name="test2" duration-ms="8" started-at="2020-06-06T16:18:11Z" finished-at="2020-06-06T16:18:11Z">
          <exception class="java.lang.AssertionError">
            <message>
              <![CDATA[The following asserts failed:
Logging out falied expected [false] but found [true]]]>
            </message>
            <full-stacktrace>
              <![CDATA[java.lang.AssertionError: The following asserts failed:
Logging out falied expected [false] but found [true]
	at org.testng.asserts.SoftAssert.assertAll(SoftAssert.java:38)
	at MyTest.SoftAssertConcepts.test2(SoftAssertConcepts.java:44)
	at sun.reflect.NativeMethodAccessorImpl.invoke0(Native Method)
	at sun.reflect.NativeMethodAccessorImpl.invoke(Unknown Source)
	at sun.reflect.DelegatingMethodAccessorImpl.invoke(Unknown Source)
	at java.lang.reflect.Method.invoke(Unknown Source)
	at org.testng.internal.MethodInvocationHelper.invokeMethod(MethodInvocationHelper.java:85)
	at org.testng.internal.Invoker.invokeMethod(Invoker.java:663)
	at org.testng.internal.Invoker.invokeTestMethod(Invoker.java:849)
	at org.testng.internal.Invoker.invokeTestMethods(Invoker.java:1157)
	at org.testng.internal.TestMethodWorker.invokeTestMethods(TestMethodWorker.java:124)
	at org.testng.internal.TestMethodWorker.run(TestMethodWorker.java:108)
	at org.testng.TestRunner.privateRun(TestRunner.java:771)
	at org.testng.TestRunner.run(TestRunner.java:621)
	at org.testng.SuiteRunner.runTest(SuiteRunner.java:357)
	at org.testng.SuiteRunner.runSequentially(SuiteRunner.java:352)
	at org.testng.SuiteRunner.privateRun(SuiteRunner.java:310)
	at org.testng.SuiteRunner.run(SuiteRunner.java:259)
	at org.testng.SuiteRunnerWorker.runSuite(SuiteRunnerWorker.java:52)
	at org.testng.SuiteRunnerWorker.run(SuiteRunnerWorker.java:86)
	at org.testng.TestNG.runSuitesSequentially(TestNG.java:1200)
	at org.testng.TestNG.runSuitesLocally(TestNG.java:1125)
	at org.testng.TestNG.run(TestNG.java:1033)
	at org.testng.remote.RemoteTestNG.run(RemoteTestNG.java:111)
	at org.testng.remote.RemoteTestNG.initAndRun(RemoteTestNG.java:204)
	at org.testng.remote.RemoteTestNG.main(RemoteTestNG.java:175)
]]>
            </full-stacktrace>
          </exception> <!-- java.lang.AssertionError -->
          <reporter-output>
          </reporter-output>
        </test-method> <!-- test2 -->
      </class> <!-- MyTest.SoftAssertConcepts -->
    </test> <!-- Default test -->
  </suite> <!-- Default suite -->
</testng-results>
